Workbook

Sheet Team
A1: SchoolFood — tiến độ nhóm
A2: Điền tên ở cột B. Số liệu tự tính từ sheet Cong viec, Nghiem thu, Loi; không sửa ô công thức.
A3: Kế hoạch và chi tiết task: plan_final.md. Quy trình: CLAUDE.md. Không tự đánh dấu thay người khác.
A5: Mã | B5: Tên thành viên | C5: Vai trò | D5: Số task | E5: Đã xong | F5: Tỷ lệ | G5: Đang làm | H5: Bị chặn | I5: Chờ mình review | J5: NT được giao | K5: NT đạt
A6: TV1 | C6: Dữ liệu & migration, tích hợp | D6: =COUNTIFS('Cong viec'!$D$6:$D$57,A6) | E6: =SUMIFS('Cong viec'!$N$6:$N$57,'Cong viec'!$D$6:$D$57,A6) | F6: =IF(D6=0,0,E6/D6) | G6: =COUNTIFS('Cong viec'!$D$6:$D$57,A6,'Cong viec'!$J$6:$J$57,"Đang làm") | H6: =COUNTIFS('Cong viec'!$D$6:$D$57,A6,'Cong viec'!$J$6:$J$57,"Bị chặn") | I6: =COUNTIFS('Cong viec'!$E$6:$E$57,A6,'Cong viec'!$J$6:$J$57,"Chờ review") | J6: =COUNTIFS('Nghiem thu'!$D$6:$D$49,A6) | K6: =SUMIFS('Nghiem thu'!$K$6:$K$49,'Nghiem thu'!$D$6:$D$49,A6)
A7: TV2 | C7: Nghiệp vụ backend (service) | D7: =COUNTIFS('Cong viec'!$D$6:$D$57,A7) | E7: =SUMIFS('Cong viec'!$N$6:$N$57,'Cong viec'!$D$6:$D$57,A7) | F7: =IF(D7=0,0,E7/D7) | G7: =COUNTIFS('Cong viec'!$D$6:$D$57,A7,'Cong viec'!$J$6:$J$57,"Đang làm") | H7: =COUNTIFS('Cong viec'!$D$6:$D$57,A7,'Cong viec'!$J$6:$J$57,"Bị chặn") | I7: =COUNTIFS('Cong viec'!$E$6:$E$57,A7,'Cong viec'!$J$6:$J$57,"Chờ review") | J7: =COUNTIFS('Nghiem thu'!$D$6:$D$49,A7) | K7: =SUMIFS('Nghiem thu'!$K$6:$K$49,'Nghiem thu'!$D$6:$D$49,A7)
A8: TV3 | C8: Giao diện chính, router | D8: =COUNTIFS('Cong viec'!$D$6:$D$57,A8) | E8: =SUMIFS('Cong viec'!$N$6:$N$57,'Cong viec'!$D$6:$D$57,A8) | F8: =IF(D8=0,0,E8/D8) | G8: =COUNTIFS('Cong viec'!$D$6:$D$57,A8,'Cong viec'!$J$6:$J$57,"Đang làm") | H8: =COUNTIFS('Cong viec'!$D$6:$D$57,A8,'Cong viec'!$J$6:$J$57,"Bị chặn") | I8: =COUNTIFS('Cong viec'!$E$6:$E$57,A8,'Cong viec'!$J$6:$J$57,"Chờ review") | J8: =COUNTIFS('Nghiem thu'!$D$6:$D$49,A8) | K8: =SUMIFS('Nghiem thu'!$K$6:$K$49,'Nghiem thu'!$D$6:$D$49,A8)
A9: TV4 | C9: API & quyền | D9: =COUNTIFS('Cong viec'!$D$6:$D$57,A9) | E9: =SUMIFS('Cong viec'!$N$6:$N$57,'Cong viec'!$D$6:$D$57,A9) | F9: =IF(D9=0,0,E9/D9) | G9: =COUNTIFS('Cong viec'!$D$6:$D$57,A9,'Cong viec'!$J$6:$J$57,"Đang làm") | H9: =COUNTIFS('Cong viec'!$D$6:$D$57,A9,'Cong viec'!$J$6:$J$57,"Bị chặn") | I9: =COUNTIFS('Cong viec'!$E$6:$E$57,A9,'Cong viec'!$J$6:$J$57,"Chờ review") | J9: =COUNTIFS('Nghiem thu'!$D$6:$D$49,A9) | K9: =SUMIFS('Nghiem thu'!$K$6:$K$49,'Nghiem thu'!$D$6:$D$49,A9)
A10: TV5 | C10: Giao diện bổ sung, kiểm thử UI | D10: =COUNTIFS('Cong viec'!$D$6:$D$57,A10) | E10: =SUMIFS('Cong viec'!$N$6:$N$57,'Cong viec'!$D$6:$D$57,A10) | F10: =IF(D10=0,0,E10/D10) | G10: =COUNTIFS('Cong viec'!$D$6:$D$57,A10,'Cong viec'!$J$6:$J$57,"Đang làm") | H10: =COUNTIFS('Cong viec'!$D$6:$D$57,A10,'Cong viec'!$J$6:$J$57,"Bị chặn") | I10: =COUNTIFS('Cong viec'!$E$6:$E$57,A10,'Cong viec'!$J$6:$J$57,"Chờ review") | J10: =COUNTIFS('Nghiem thu'!$D$6:$D$49,A10) | K10: =SUMIFS('Nghiem thu'!$K$6:$K$49,'Nghiem thu'!$D$6:$D$49,A10)
A11: TV6 | C11: Audit, test, vận hành, nghiệm thu | D11: =COUNTIFS('Cong viec'!$D$6:$D$57,A11) | E11: =SUMIFS('Cong viec'!$N$6:$N$57,'Cong viec'!$D$6:$D$57,A11) | F11: =IF(D11=0,0,E11/D11) | G11: =COUNTIFS('Cong viec'!$D$6:$D$57,A11,'Cong viec'!$J$6:$J$57,"Đang làm") | H11: =COUNTIFS('Cong viec'!$D$6:$D$57,A11,'Cong viec'!$J$6:$J$57,"Bị chặn") | I11: =COUNTIFS('Cong viec'!$E$6:$E$57,A11,'Cong viec'!$J$6:$J$57,"Chờ review") | J11: =COUNTIFS('Nghiem thu'!$D$6:$D$49,A11) | K11: =SUMIFS('Nghiem thu'!$K$6:$K$49,'Nghiem thu'!$D$6:$D$49,A11)
C12: Tổng | D12: =SUM(D6:D11) | E12: =SUM(E6:E11) | F12: =IF(D12=0,0,E12/D12) | G12: =SUM(G6:G11) | H12: =SUM(H6:H11) | I12: =SUM(I6:I11) | J12: =SUM(J6:J11) | K12: =SUM(K6:K11)
A14: Theo đợt
A15: Đợt | B15: Nội dung | D15: Số task | E15: Đã xong | F15: Tỷ lệ | G15: NT | H15: NT đạt | I15: Lỗi còn mở
A16: Đợt 1 | B16: Bảo mật, thực đơn cố định, email phụ huynh, deploy (BE/FE/SF39–42/SF48/SF54) | D16: =COUNTIFS('Cong viec'!$B$6:$B$57,"Đợt 1") | E16: =SUMIFS('Cong viec'!$N$6:$N$57,'Cong viec'!$B$6:$B$57,"Đợt 1") | F16: =IF(D16=0,0,E16/D16) | G16: =COUNTIFS('Nghiem thu'!$B$6:$B$49,"PR*")+COUNTIFS('Nghiem thu'!$B$6:$B$49,"G2.1*") | H16: =SUMIFS('Nghiem thu'!$K$6:$K$49,'Nghiem thu'!$B$6:$B$49,"PR*")+SUMIFS('Nghiem thu'!$K$6:$K$49,'Nghiem thu'!$B$6:$B$49,"G2.1*") | I16: =COUNTIFS('Loi'!$F$5:$F$35,"<>Đóng",'Loi'!$A$5:$A$35,"ISSUE*")
A17: Đợt 2 | B17: Chuỗi G2: nhu cầu → đặt → nhận → xuất → chi phí (SF55–SF72) | D17: =COUNTIFS('Cong viec'!$B$6:$B$57,"Đợt 2") | E17: =SUMIFS('Cong viec'!$N$6:$N$57,'Cong viec'!$B$6:$B$57,"Đợt 2") | F17: =IF(D17=0,0,E17/D17) | G17: =COUNTIFS('Nghiem thu'!$B$6:$B$49,"G2.3*")+COUNTIFS('Nghiem thu'!$B$6:$B$49,"G2.4*")+COUNTIFS('Nghiem thu'!$B$6:$B$49,"G2.5*") | H17: =SUMIFS('Nghiem thu'!$K$6:$K$49,'Nghiem thu'!$B$6:$B$49,"G2.3*")+SUMIFS('Nghiem thu'!$K$6:$K$49,'Nghiem thu'!$B$6:$B$49,"G2.4*")+SUMIFS('Nghiem thu'!$K$6:$K$49,'Nghiem thu'!$B$6:$B$49,"G2.5*")

Sheet Cong viec
A1: SchoolFood — công việc theo plan_final.md (cập nhật 01/10/2026)
A2: Lọc cột Người làm để thấy việc của mình. Người làm cập nhật Trạng thái, PR/bằng chứng; Reviewer cập nhật Review.
A3: Được tính xong = Hoàn tất + Review Đạt + có bằng chứng + reviewer khác người làm. Chi tiết từng task: plan_final.md §10.
A5: Mã | B5: Đợt | C5: Nhóm | D5: Người làm | E5: Reviewer | F5: Công việc | G5: Cần xong trước | H5: Điều kiện xong | I5: Ngày dự kiến | J5: Trạng thái | K5: Review | L5: PR / bằng chứng | M5: Ghi chú, trở ngại | N5: Được tính xong | O5: Có thể bắt đầu
A6: BE-01 | B6: Đợt 1 | C6: Backend | D6: TV1 | E6: TV6 | F6: ISSUE-001: lệnh sf_legacy_db_check nâng cấp DB cũ (f00048d) | G6: Không | H6: DB sạch và DB legacy rỗng migrate tới head; ledger audit --strict đạt; DB legacy có dữ liệu bị từ chối rõ | I6: N2–N5 | J6: Chưa làm | K6: Chưa | N6: =IF(AND(J6="Hoàn tất",K6="Đạt",L6<>"",D6<>E6),1,0) | O6: =IF(N6=1,"Xong","Có thể bắt đầu")
A7: BE-02 | B7: Đợt 1 | C7: Backend | D7: TV1 | E7: TV6 | F7: Migration 0014: group manager/principal, LoginThrottle, AuditLog + trigger append-only | G7: Không | H7: UPDATE/DELETE AuditLog bị trigger chặn; migrate tiến/lùi trên DB sạch | I7: N1 | J7: Chưa làm | K7: Chưa | N7: =IF(AND(J7="Hoàn tất",K7="Đạt",L7<>"",D7<>E7),1,0) | O7: =IF(N7=1,"Xong","Có thể bắt đầu")
A8: BE-03 | B8: Đợt 1 | C8: Backend | D8: TV1 | E8: TV6 | F8: Migration 0015–0016 (SF49): công thức Decimal(14,6), MenuVersion/Item, SchoolHoliday, DayMenuSnapshot | G8: BE-02 | H8: Lưu được 0.0004 kg; quantity 0 bị chặn; version đã hiệu lực và snapshot bất biến | I8: N3 | J8: Chưa làm | K8: Chưa | N8: =IF(AND(J8="Hoàn tất",K8="Đạt",L8<>"",D8<>E8),1,0) | O8: =IF(N8=1,"Xong",IF(AND(SUMIFS($N$6:$N$57,$A$6:$A$57,"BE-02")=1),"Có thể bắt đầu","Chờ task trước"))
A9: BE-04 | B9: Đợt 1 | C9: Backend | D9: TV1 | E9: TV6 | F9: crypto_fields.py + migration 0017–0018: Student, ParentContact (email mã hóa), NotificationLog | G9: BE-03 | H9: DB không chứa email rõ; mã hóa/giải mã đúng; xoay khóa vẫn đọc bản cũ | I9: N4 | J9: Chưa làm | K9: Chưa | N9: =IF(AND(J9="Hoàn tất",K9="Đạt",L9<>"",D9<>E9),1,0) | O9: =IF(N9=1,"Xong",IF(AND(SUMIFS($N$6:$N$57,$A$6:$A$57,"BE-03")=1),"Có thể bắt đầu","Chờ task trước"))
A10: BE-05 | B10: Đợt 1 | C10: Backend | D10: TV2 | E10: TV4 | F10: ISSUE-007: làm tròn tiền thống nhất (line_value, money) | G10: Không | H10: 0.500 × 0.01 = 0.01 ở nháp, chi tiết, sổ kho, báo cáo; bỏ hết round() | I10: N1 | J10: Chưa làm | K10: Chưa | N10: =IF(AND(J10="Hoàn tất",K10="Đạt",L10<>"",D10<>E10),1,0) | O10: =IF(N10=1,"Xong","Có thể bắt đầu")
A11: BE-06 | B11: Đợt 1 | C11: Backend | D11: TV2 | E11: TV4 | F11: ISSUE-003 + SF50: quy đổi g/kg, ml/lít; thay công thức món (recipe_services.py) | G11: BE-03 | H11: 60 g → 0.060000 kg; 0,4 g giữ đúng; 0,0004 g, kg↔lít, trùng food, float → 400 | I11: N2–N3 | J11: Chưa làm | K11: Chưa | N11: =IF(AND(J11="Hoàn tất",K11="Đạt",L11<>"",D11<>E11),1,0) | O11: =IF(N11=1,"Xong",IF(AND(SUMIFS($N$6:$N$57,$A$6:$A$57,"BE-03")=1),"Có thể bắt đầu","Chờ task trước"))
A12: BE-07 | B12: Đợt 1 | C12: Backend | D12: TV2 | E12: TV4 | F12: SF52: menu_services.py thực đơn cố định T2–T6, ngày nghỉ, snapshot ngày | G12: BE-03 | H12: Version đúng ngày hiệu lực; snapshot không đổi khi sửa công thức; T7/CN/lễ = nghỉ; chặn version lùi ngày/thiếu thứ | I12: N4–N5 | J12: Chưa làm | K12: Chưa | N12: =IF(AND(J12="Hoàn tất",K12="Đạt",L12<>"",D12<>E12),1,0) | O12: =IF(N12=1,"Xong",IF(AND(SUMIFS($N$6:$N$57,$A$6:$A$57,"BE-03")=1),"Có thể bắt đầu","Chờ task trước"))
A13: BE-08 | B13: Đợt 1 | C13: Backend | D13: TV2 | E13: TV4 | F13: Email thực đơn 6h30: notifications.py, mailer.py, send_daily_menu, run_scheduler, API hủy nhận | G13: BE-04, BE-07 | H13: 1 thư/email/ngày, không lộ địa chỉ người khác; chạy lại không gửi trùng; ngày nghỉ skipped; hủy nhận chạy; dry-run không gửi | I13: N6–N7 | J13: Chưa làm | K13: Chưa | N13: =IF(AND(J13="Hoàn tất",K13="Đạt",L13<>"",D13<>E13),1,0) | O13: =IF(N13=1,"Xong",IF(AND(SUMIFS($N$6:$N$57,$A$6:$A$57,"BE-04")=1,SUMIFS($N$6:$N$57,$A$6:$A$57,"BE-07")=1),"Có thể bắt đầu","Chờ task trước"))
A14: BE-09 | B14: Đợt 1 | C14: Backend | D14: TV4 | E14: TV2 | F14: http_input.py + @json_api; áp dụng cho mọi view (ISSUE-004/005/006/008) | G14: Không | H14: JSON mảng/null, "false", float, ngày sai, số lẻ vượt scale → 400 JSON, không ghi dòng nào; test cũ xanh | I14: N1 | J14: Chưa làm | K14: Chưa | N14: =IF(AND(J14="Hoàn tất",K14="Đạt",L14<>"",D14<>E14),1,0) | O14: =IF(N14=1,"Xong","Có thể bắt đầu")
A15: BE-10 | B15: Đợt 1 | C15: Backend | D15: TV4 | E15: TV2 | F15: Vai trò Quản lý/Hiệu trưởng, decorator, khóa đăng nhập sai, phiên 30'/12h, validator mật khẩu | G15: BE-02, BE-09 | H15: Sai 5 lần → 429; 20 lần/IP → 429; phiên quá hạn → 401; principal ghi → 403; user không vai trò → 403 | I15: N2–N3 | J15: Chưa làm | K15: Chưa | N15: =IF(AND(J15="Hoàn tất",K15="Đạt",L15<>"",D15<>E15),1,0) | O15: =IF(N15=1,"Xong",IF(AND(SUMIFS($N$6:$N$57,$A$6:$A$57,"BE-02")=1,SUMIFS($N$6:$N$57,$A$6:$A$57,"BE-09")=1),"Có thể bắt đầu","Chờ task trước"))
A16: BE-11 | B16: Đợt 1 | C16: Backend | D16: TV4 | E16: TV2 | F16: API quản lý tài khoản /api/users/ (tạo, sửa vai trò, khóa, đặt lại mật khẩu) | G16: BE-10 | H16: Chặn tự khóa, bỏ principal cuối, sửa superuser; khóa → đá phiên; audit không chứa mật khẩu | I16: N3–N4 | J16: Chưa làm | K16: Chưa | N16: =IF(AND(J16="Hoàn tất",K16="Đạt",L16<>"",D16<>E16),1,0) | O16: =IF(N16=1,"Xong",IF(AND(SUMIFS($N$6:$N$57,$A$6:$A$57,"BE-10")=1),"Có thể bắt đầu","Chờ task trước"))
A17: BE-12 | B17: Đợt 1 | C17: Backend | D17: TV4 | E17: TV2 | F17: ISSUE-002 + ISSUE-011: API lớp (grade, enrolled) và ngày ăn SF46 (meal_views.py) | G17: BE-09 | H17: Lớp 30 HS: −1/31 → 400, null ≠ 0; GET không ghi; version cũ → 409; không còn except Exception | I17: N4 | J17: Chưa làm | K17: Chưa | N17: =IF(AND(J17="Hoàn tất",K17="Đạt",L17<>"",D17<>E17),1,0) | O17: =IF(N17=1,"Xong",IF(AND(SUMIFS($N$6:$N$57,$A$6:$A$57,"BE-09")=1),"Có thể bắt đầu","Chờ task trước"))
A18: BE-13 | B18: Đợt 1 | C18: Backend | D18: TV4 | E18: TV2 | F18: API thực đơn: /api/menu/week, versions, holidays, dishes/<id> | G18: BE-07, BE-09 | H18: Đọc cho manager + principal; ghi chỉ manager; lỗi đúng mã; audit ghi đủ | I18: N5–N6 | J18: Chưa làm | K18: Chưa | N18: =IF(AND(J18="Hoàn tất",K18="Đạt",L18<>"",D18<>E18),1,0) | O18: =IF(N18=1,"Xong",IF(AND(SUMIFS($N$6:$N$57,$A$6:$A$57,"BE-07")=1,SUMIFS($N$6:$N$57,$A$6:$A$57,"BE-09")=1),"Có thể bắt đầu","Chờ task trước"))
A19: BE-14 | B19: Đợt 1 | C19: Backend | D19: TV6 | E19: TV1 | F19: API học sinh + import CSV (dry-run) + xem email phụ huynh | G19: BE-04, BE-09 | H19: Danh sách chỉ email che; CSV 1 dòng lỗi → không ghi gì; principal không xem được email; xóa bé xóa email | I19: N5–N6 | J19: Chưa làm | K19: Chưa | N19: =IF(AND(J19="Hoàn tất",K19="Đạt",L19<>"",D19<>E19),1,0) | O19: =IF(N19=1,"Xong",IF(AND(SUMIFS($N$6:$N$57,$A$6:$A$57,"BE-04")=1,SUMIFS($N$6:$N$57,$A$6:$A$57,"BE-09")=1),"Có thể bắt đầu","Chờ task trước"))
A20: BE-15 | B20: Đợt 1 | C20: Backend | D20: TV6 | E20: TV1 | F20: audit.py + GET /api/audit-logs/ + chèn audit.record vào view kho/lớp/món | G20: BE-02, BE-09 | H20: Mọi nhóm thao tác có audit; rollback không để lại audit; không mật khẩu/email; manager GET → 403 | I20: N2–N3 | J20: Chưa làm | K20: Chưa | N20: =IF(AND(J20="Hoàn tất",K20="Đạt",L20<>"",D20<>E20),1,0) | O20: =IF(N20=1,"Xong",IF(AND(SUMIFS($N$6:$N$57,$A$6:$A$57,"BE-02")=1,SUMIFS($N$6:$N$57,$A$6:$A$57,"BE-09")=1),"Có thể bắt đầu","Chờ task trước"))
A21: BE-16 | B21: Đợt 1 | C21: Backend | D21: TV6 | E21: TV1 | F21: ISSUE-009: test_security.py ma trận quyền/CSRF cho mọi route + ca phiên | G21: BE-10, BE-11, BE-15 | H21: Route chưa khai quyền làm test fail; đủ ca 401/403/CSRF/405/phiên | I21: N1–N4 | J21: Chưa làm | K21: Chưa | N21: =IF(AND(J21="Hoàn tất",K21="Đạt",L21<>"",D21<>E21),1,0) | O21: =IF(N21=1,"Xong",IF(AND(SUMIFS($N$6:$N$57,$A$6:$A$57,"BE-10")=1,SUMIFS($N$6:$N$57,$A$6:$A$57,"BE-11")=1,SUMIFS($N$6:$N$57,$A$6:$A$57,"BE-15")=1),"Có thể bắt đầu","Chờ task trước"))
A22: BE-17 | B22: Đợt 1 | C22: Backend | D22: TV6 | E22: TV1 | F22: Vận hành: nginx CSP + X-Real-IP + rate-limit, service scheduler, backup cron, docs/SECURITY.md | G22: BE-08, BE-10 | H22: Không lỗi CSP trên build production; check --deploy sạch; backup → restore DB tạm khớp | I22: N7 | J22: Chưa làm | K22: Chưa | N22: =IF(AND(J22="Hoàn tất",K22="Đạt",L22<>"",D22<>E22),1,0) | O22: =IF(N22=1,"Xong",IF(AND(SUMIFS($N$6:$N$57,$A$6:$A$57,"BE-08")=1,SUMIFS($N$6:$N$57,$A$6:$A$57,"BE-10")=1),"Có thể bắt đầu","Chờ task trước"))
A23: BE-18 | B23: Đợt 1 | C23: Backend | D23: TV6 | E23: TV1 | F23: seed_demo --scenario security (user, lớp, món, thực đơn, học sinh email giả) | G23: BE-02 | H23: Chạy lại không nhân bản dữ liệu; từ chối khi DEBUG=False; không in mật khẩu | I23: N1 | J23: Chưa làm | K23: Chưa | N23: =IF(AND(J23="Hoàn tất",K23="Đạt",L23<>"",D23<>E23),1,0) | O23: =IF(N23=1,"Xong",IF(AND(SUMIFS($N$6:$N$57,$A$6:$A$57,"BE-02")=1),"Có thể bắt đầu","Chờ task trước"))
A24: FE-01 | B24: Đợt 1 | C24: Frontend | D24: TV3 | E24: TV5 | F24: Vai trò mới ở frontend: nhãn Quản lý/Hiệu trưởng, khóa nút ghi, đăng nhập 429/403, hết phiên | G24: BE-10 | H24: Hiệu trưởng thấy nút khóa kèm tooltip; 429 báo số phút; hết phiên về /dang-nhap | I24: N4 | J24: Chưa làm | K24: Chưa | N24: =IF(AND(J24="Hoàn tất",K24="Đạt",L24<>"",D24<>E24),1,0) | O24: =IF(N24=1,"Xong",IF(AND(SUMIFS($N$6:$N$57,$A$6:$A$57,"BE-10")=1),"Có thể bắt đầu","Chờ task trước"))
A25: FE-02 | B25: Đợt 1 | C25: Frontend | D25: TV3 | E25: TV5 | F25: Màn Tài khoản /tai-khoan (chỉ Hiệu trưởng) | G25: BE-11, FE-01 | H25: Tạo, đổi vai trò, khóa/mở, đặt lại mật khẩu; lỗi validator hiện đúng ô | I25: N5 | J25: Chưa làm | K25: Chưa | N25: =IF(AND(J25="Hoàn tất",K25="Đạt",L25<>"",D25<>E25),1,0) | O25: =IF(N25=1,"Xong",IF(AND(SUMIFS($N$6:$N$57,$A$6:$A$57,"BE-11")=1,SUMIFS($N$6:$N$57,$A$6:$A$57,"FE-01")=1),"Có thể bắt đầu","Chờ task trước"))
A26: FE-03 | B26: Đợt 1 | C26: Frontend | D26: TV5 | E26: TV3 | F26: Màn Nhật ký /nhat-ky: lọc người/hành động/đối tượng/ngày, drawer trước → sau | G26: BE-15, FE-01 | H26: Phân trang 50 dòng; Quản lý không thấy mục menu | I26: N5 | J26: Chưa làm | K26: Chưa | N26: =IF(AND(J26="Hoàn tất",K26="Đạt",L26<>"",D26<>E26),1,0) | O26: =IF(N26=1,"Xong",IF(AND(SUMIFS($N$6:$N$57,$A$6:$A$57,"BE-15")=1,SUMIFS($N$6:$N$57,$A$6:$A$57,"FE-01")=1),"Có thể bắt đầu","Chờ task trước"))
A27: FE-04 | B27: Đợt 1 | C27: Frontend | D27: TV3 | E27: TV5 | F27: Tab Thực đơn tuần trong /mon-an: lưới T2–T6, sửa thực đơn cố định, lịch sử phiên bản | G27: BE-13 | H27: Ngày nghỉ và ngày chưa lập hiển thị riêng; không chọn ngày áp dụng ≤ hôm nay | I27: N6–N7 | J27: Chưa làm | K27: Chưa | N27: =IF(AND(J27="Hoàn tất",K27="Đạt",L27<>"",D27<>E27),1,0) | O27: =IF(N27=1,"Xong",IF(AND(SUMIFS($N$6:$N$57,$A$6:$A$57,"BE-13")=1),"Có thể bắt đầu","Chờ task trước"))
A28: FE-05 | B28: Đợt 1 | C28: Frontend | D28: TV5 | E28: TV3 | F28: Ngày nghỉ (thêm/xóa) + form công thức 6 số lẻ, đơn vị g/ml | G28: BE-13 | H28: Nhập 0,4 g lưu đúng; lỗi đơn vị hiện tại dòng | I28: N6 | J28: Chưa làm | K28: Chưa | N28: =IF(AND(J28="Hoàn tất",K28="Đạt",L28<>"",D28<>E28),1,0) | O28: =IF(N28=1,"Xong",IF(AND(SUMIFS($N$6:$N$57,$A$6:$A$57,"BE-13")=1),"Có thể bắt đầu","Chờ task trước"))
A29: FE-06 | B29: Đợt 1 | C29: Frontend | D29: TV5 | E29: TV3 | F29: Tab Học sinh trong /lop-hoc: email che, nút Hiện, import CSV có xem trước | G29: BE-14 | H29: Hiệu trưởng không có nút Hiện; CSV lỗi hiện từng dòng | I29: N7 | J29: Chưa làm | K29: Chưa | N29: =IF(AND(J29="Hoàn tất",K29="Đạt",L29<>"",D29<>E29),1,0) | O29: =IF(N29=1,"Xong",IF(AND(SUMIFS($N$6:$N$57,$A$6:$A$57,"BE-14")=1),"Có thể bắt đầu","Chờ task trước"))
A30: FE-07 | B30: Đợt 1 | C30: Frontend | D30: TV3 | E30: TV5 | F30: Tab Thư thực đơn (nhật ký, gửi lại, gửi thử) + trang công khai /huy-nhan/:token | G30: BE-08 | H30: Nhãn "Chế độ thử" khi dry-run; trang hủy nhận cần bấm xác nhận | I30: N7 | J30: Chưa làm | K30: Chưa | N30: =IF(AND(J30="Hoàn tất",K30="Đạt",L30<>"",D30<>E30),1,0) | O30: =IF(N30=1,"Xong",IF(AND(SUMIFS($N$6:$N$57,$A$6:$A$57,"BE-08")=1),"Có thể bắt đầu","Chờ task trước"))
A31: FE-08 | B31: Đợt 1 | C31: Frontend | D31: TV5 | E31: TV3 | F31: SF45/SF47: lớp có sĩ số + khối; bảng nhập suất theo ngày, chốt/mở lại | G31: BE-12 | H31: −1/31 bị chặn tại ô; ô trống khác 0; version cũ báo tải lại | I31: N5–N6 | J31: Chưa làm | K31: Chưa | N31: =IF(AND(J31="Hoàn tất",K31="Đạt",L31<>"",D31<>E31),1,0) | O31: =IF(N31=1,"Xong",IF(AND(SUMIFS($N$6:$N$57,$A$6:$A$57,"BE-12")=1),"Có thể bắt đầu","Chờ task trước"))
A32: FE-09 | B32: Đợt 1 | C32: Frontend | D32: TV3 | E32: TV5 | F32: Cập nhật UI_GUIDE theo vai trò mới; ảnh evidence 1280/375 mọi màn đợt 1 | G32: FE-02, FE-04, FE-07 | H32: Ảnh lưu outputs/team-6/evidence/SEC_*.png; npm run build đạt | I32: N8 | J32: Chưa làm | K32: Chưa | N32: =IF(AND(J32="Hoàn tất",K32="Đạt",L32<>"",D32<>E32),1,0) | O32: =IF(N32=1,"Xong",IF(AND(SUMIFS($N$6:$N$57,$A$6:$A$57,"FE-02")=1,SUMIFS($N$6:$N$57,$A$6:$A$57,"FE-04")=1,SUMIFS($N$6:$N$57,$A$6:$A$57,"FE-07")=1),"Có thể bắt đầu","Chờ task trước"))
A33: SF39 | B33: Đợt 1 | C33: Deploy | D33: TV3 | E33: TV5 | F33: Build giao diện cho production (đã có trong SF38 #33: kiểm và bổ sung) | G33: Không | H33: Build production chạy qua nginx, không gọi localhost | I33: N2 | J33: Chưa làm | K33: Chưa | N33: =IF(AND(J33="Hoàn tất",K33="Đạt",L33<>"",D33<>E33),1,0) | O33: =IF(N33=1,"Xong","Có thể bắt đầu")
A34: SF40 | B34: Đợt 1 | C34: Deploy | D34: TV4 | E34: TV2 | F34: Kiểm tra cấu hình production (DEBUG, secret, HTTPS, cookie, CSRF origin) | G34: BE-10 | H34: check --deploy sạch trên EC2; không lộ secret trong log | I34: N6 | J34: Chưa làm | K34: Chưa | N34: =IF(AND(J34="Hoàn tất",K34="Đạt",L34<>"",D34<>E34),1,0) | O34: =IF(N34=1,"Xong",IF(AND(SUMIFS($N$6:$N$57,$A$6:$A$57,"BE-10")=1),"Có thể bắt đầu","Chờ task trước"))
A35: SF41 | B35: Đợt 1 | C35: Deploy | D35: TV5 | E35: TV3 | F35: Kiểm tra tên miền và giao diện public schoolfoodusth.store | G35: SF39, SF40 | H35: HTTPS, đăng nhập, thao tác chính chạy trên domain thật | I35: N7 | J35: Chưa làm | K35: Chưa | N35: =IF(AND(J35="Hoàn tất",K35="Đạt",L35<>"",D35<>E35),1,0) | O35: =IF(N35=1,"Xong",IF(AND(SUMIFS($N$6:$N$57,$A$6:$A$57,"SF39")=1,SUMIFS($N$6:$N$57,$A$6:$A$57,"SF40")=1),"Có thể bắt đầu","Chờ task trước"))
A36: SF42 | B36: Đợt 1 | C36: Deploy | D36: TV6 | E36: TV1 | F36: Bàn giao bản deploy + diễn tập khôi phục từ backup | G36: SF41, BE-17 | H36: Restore backup vào DB tạm thành công, có biên bản | I36: N8 | J36: Chưa làm | K36: Chưa | N36: =IF(AND(J36="Hoàn tất",K36="Đạt",L36<>"",D36<>E36),1,0) | O36: =IF(N36=1,"Xong",IF(AND(SUMIFS($N$6:$N$57,$A$6:$A$57,"SF41")=1,SUMIFS($N$6:$N$57,$A$6:$A$57,"BE-17")=1),"Có thể bắt đầu","Chờ task trước"))
A37: SF48 | B37: Đợt 1 | C37: Nghiệm thu | D37: TV6 | E37: TV1 | F37: Nghiệm thu lớp và suất (NT35–NT37) | G37: BE-12, FE-08 | H37: NT35–NT37 đạt trên máy thứ hai | I37: N8 | J37: Chưa làm | K37: Chưa | N37: =IF(AND(J37="Hoàn tất",K37="Đạt",L37<>"",D37<>E37),1,0) | O37: =IF(N37=1,"Xong",IF(AND(SUMIFS($N$6:$N$57,$A$6:$A$57,"BE-12")=1,SUMIFS($N$6:$N$57,$A$6:$A$57,"FE-08")=1),"Có thể bắt đầu","Chờ task trước"))
A38: SF54 | B38: Đợt 1 | C38: Nghiệm thu | D38: TV6 | E38: TV1 | F38: Nghiệm thu món và thực đơn (NT14–NT19) | G38: BE-13, FE-04, FE-05 | H38: NT14–NT19 đạt; thịt 60 g + 10 g = 70 g/suất | I38: N8 | J38: Chưa làm | K38: Chưa | N38: =IF(AND(J38="Hoàn tất",K38="Đạt",L38<>"",D38<>E38),1,0) | O38: =IF(N38=1,"Xong",IF(AND(SUMIFS($N$6:$N$57,$A$6:$A$57,"BE-13")=1,SUMIFS($N$6:$N$57,$A$6:$A$57,"FE-04")=1,SUMIFS($N$6:$N$57,$A$6:$A$57,"FE-05")=1),"Có thể bắt đầu","Chờ task trước"))
A39: QA-01 | B39: Đợt 1 | C39: Nghiệm thu | D39: TV6 | E39: TV1 | F39: Nghiệm thu bảo mật và email (NT01–NT13, NT20–NT34) | G39: BE-16, BE-17, FE-09 | H39: Mọi NT của khối PR1/PR3/PR4 đạt, có bằng chứng | I39: N8 | J39: Chưa làm | K39: Chưa | N39: =IF(AND(J39="Hoàn tất",K39="Đạt",L39<>"",D39<>E39),1,0) | O39: =IF(N39=1,"Xong",IF(AND(SUMIFS($N$6:$N$57,$A$6:$A$57,"BE-16")=1,SUMIFS($N$6:$N$57,$A$6:$A$57,"BE-17")=1,SUMIFS($N$6:$N$57,$A$6:$A$57,"FE-09")=1),"Có thể bắt đầu","Chờ task trước"))
A40: SF55 | B40: Đợt 2 | C40: Backend | D40: TV1 | E40: TV6 | F40: Contract + migration nhu cầu và phân bổ (DemandRevision/Line, StockAllocation) | G40: SF54 | H40: Thứ tự khóa theo plan_final §3; trigger trạng thái | J40: Chưa làm | K40: Chưa | N40: =IF(AND(J40="Hoàn tất",K40="Đạt",L40<>"",D40<>E40),1,0) | O40: =IF(N40=1,"Xong",IF(AND(SUMIFS($N$6:$N$57,$A$6:$A$57,"SF54")=1),"Có thể bắt đầu","Chờ task trước"))
A41: SF56 | B41: Đợt 2 | C41: Backend | D41: TV2 | E41: TV4 | F41: Service tính nhu cầu + đề xuất mua/giữ hàng | G41: SF55 | H41: 300 × 70 g = 21 kg; đề xuất 21 + 1 − 5 − 4 = 13 kg | J41: Chưa làm | K41: Chưa | N41: =IF(AND(J41="Hoàn tất",K41="Đạt",L41<>"",D41<>E41),1,0) | O41: =IF(N41=1,"Xong",IF(AND(SUMIFS($N$6:$N$57,$A$6:$A$57,"SF55")=1),"Có thể bắt đầu","Chờ task trước"))
...

Sheet Nghiem thu
A1: SchoolFood — nghiệm thu (NT)
A2: Người kiểm tra không phải người viết code của task liên quan. Ghi kết quả thực tế và bằng chứng (ảnh, log, link PR).
A3: Được tính đạt = Trạng thái Đạt + có kết quả thực tế + có bằng chứng. Số liệu chuẩn: CLAUDE.md §6.
A5: Mã | B5: Khối | C5: Task liên quan | D5: Người kiểm tra | E5: Thiết lập và thao tác | F5: Kết quả mong đợi | G5: Kết quả thực tế | H5: Trạng thái | I5: Ngày chạy | J5: Bằng chứng | K5: Được tính đạt
A6: NT01 | B6: PR1 Bảo mật | C6: BE-10, BE-16 | D6: TV6 | E6: Chưa đăng nhập gọi mọi API (trừ login, csrf, unsubscribe) | F6: 401, không lộ dữ liệu | H6: Chưa chạy | K6: =IF(AND(H6="Đạt",G6<>"",J6<>""),1,0)
A7: NT02 | B7: PR1 Bảo mật | C7: BE-10, FE-01 | D7: TV6 | E7: Hiệu trưởng tạo phiếu nhập, chốt phiếu, sửa món (UI và API) | F7: Nút bị khóa có tooltip; API 403; DB không đổi | H7: Chưa chạy | K7: =IF(AND(H7="Đạt",G7<>"",J7<>""),1,0)
A8: NT03 | B8: PR1 Bảo mật | C8: BE-11, BE-15 | D8: TV6 | E8: Quản lý mở /tai-khoan, /nhat-ky và gọi /api/users/, /api/audit-logs/ | F8: Không thấy menu; API 403 | H8: Chưa chạy | K8: =IF(AND(H8="Đạt",G8<>"",J8<>""),1,0)
A9: NT04 | B9: PR1 Bảo mật | C9: BE-10 | D9: TV6 | E9: Đăng nhập sai mật khẩu 5 lần cùng username, rồi nhập đúng | F9: Lần 6 bị khóa 15 phút (429), thông báo không lộ tài khoản có tồn tại | H9: Chưa chạy | K9: =IF(AND(H9="Đạt",G9<>"",J9<>""),1,0)
A10: NT05 | B10: PR1 Bảo mật | C10: BE-10 | D10: TV6 | E10: Từ 1 IP đăng nhập sai 20 lần với 20 username khác nhau | F10: Bị khóa theo IP (429) | H10: Chưa chạy | K10: =IF(AND(H10="Đạt",G10<>"",J10<>""),1,0)
A11: NT06 | B11: PR1 Bảo mật | C11: BE-10 | D11: TV6 | E11: Đăng nhập, để yên 31 phút rồi thao tác | F11: Phải đăng nhập lại; thông báo phiên hết hạn | H11: Chưa chạy | K11: =IF(AND(H11="Đạt",G11<>"",J11<>""),1,0)
A12: NT07 | B12: PR1 Bảo mật | C12: BE-11 | D12: TV6 | E12: Hiệu trưởng khóa tài khoản Quản lý đang đăng nhập ở máy khác | F12: Máy kia bị đăng xuất ở thao tác kế tiếp | H12: Chưa chạy | K12: =IF(AND(H12="Đạt",G12<>"",J12<>""),1,0)
A13: NT08 | B13: PR1 Bảo mật | C13: BE-11 | D13: TV6 | E13: Đặt lại mật khẩu cho người đang đăng nhập | F13: Phiên cũ mất; mật khẩu mới dùng được | H13: Chưa chạy | K13: =IF(AND(H13="Đạt",G13<>"",J13<>""),1,0)
A14: NT09 | B14: PR1 Bảo mật | C14: BE-10, BE-11 | D14: TV6 | E14: Tạo tài khoản với mật khẩu 8 ký tự, "1234567890", giống username | F14: Cả ba bị từ chối với lý do tiếng Việt | H14: Chưa chạy | K14: =IF(AND(H14="Đạt",G14<>"",J14<>""),1,0)
A15: NT10 | B15: PR1 Bảo mật | C15: BE-11 | D15: TV6 | E15: Hiệu trưởng duy nhất tự khóa mình / tự đổi sang Quản lý | F15: 409, không đổi | H15: Chưa chạy | K15: =IF(AND(H15="Đạt",G15<>"",J15<>""),1,0)
A16: NT11 | B16: PR1 Bảo mật | C16: BE-15 | D16: TV1 | E16: Thực hiện tạo/chốt phiếu, sửa món, khóa user; xem nhật ký; thử UPDATE AuditLog bằng SQL | F16: Đủ dòng, có trước → sau, không mật khẩu; SQL UPDATE bị chặn | H16: Chưa chạy | K16: =IF(AND(H16="Đạt",G16<>"",J16<>""),1,0)
A17: NT12 | B17: PR1 Bảo mật | C17: BE-09 | D17: TV6 | E17: Gửi body [], {"is_active":"false"}, quantity 0.1 (số), ngày 2026-99-99 | F17: 400 JSON có field lỗi; không tạo dòng nào | H17: Chưa chạy | K17: =IF(AND(H17="Đạt",G17<>"",J17<>""),1,0)
... A49: NT46 | B49: G2.5 Xuất & chi phí | C49: SF72 | D49: TV6 | E49: Chạy sf31_ledger_audit --strict sau kịch bản đầy đủ | F49: Đạt, tồn khớp sổ | H49: Chưa chạy | K49: =IF(AND(H49="Đạt",G49<>"",J49<>""),1,0)

Sheet Loi
A1: SchoolFood — lỗi đang mở (đồng bộ plan_final.md §5)
A2: Chỉ đổi sang Đóng khi điều kiện đóng đạt và có bằng chứng (commit + test). Lỗi mới: thêm dòng ISSUE-0xx và ghi vào plan_final.md §5.
A4: Mã | B4: Ưu tiên | C4: Vấn đề | D4: Task xử lý | E4: Điều kiện đóng | F4: Trạng thái | G4: Bằng chứng
A5: ISSUE-001 | B5: P1 | C5: DB migrate tại f00048d không nâng cấp được (trùng bảng inventory_issue) | D5: BE-01 | E5: DB sạch và DB nâng cấp đều chạy; ledger đạt; không --fake mù | F5: Mở
A6: ISSUE-002 | B6: P1 | C6: API lớp bỏ qua grade | D6: BE-12 | E6: Tạo/sửa/đọc grade đúng; sai kiểu 400 | F6: Mở
A7: ISSUE-003 | B7: P1 | C7: Công thức 0,4 g lưu thành 0 | D7: BE-03, BE-06 | E7: 0,4 g giữ đúng hoặc 400 rõ | F7: Mở
A8: ISSUE-004 | B8: P1 | C8: Ngày/lượng sai làm API xuất trả 500 | D8: BE-09 | E8: 400 JSON; không phiếu mồ côi | F8: Mở
A9: ISSUE-005 | B9: P2 | C9: Body JSON mảng → 500 | D9: BE-09 | E9: 400 JSON ở mọi endpoint | F9: Mở
A10: ISSUE-006 | B10: P2 | C10: "false" lưu thành true | D10: BE-09 | E10: Chỉ nhận boolean JSON | F10: Mở
A11: ISSUE-007 | B11: P2 | C11: Phiếu 0.00 nhưng sổ 0.01 | D11: BE-05 | E11: Phiếu, sổ, báo cáo khớp | F11: Mở
A12: ISSUE-008 | B12: P2 | C12: API nhập nhận float | D12: BE-09 | E12: Float/bool/NaN → 400 | F12: Mở
A13: ISSUE-009 | B13: P1 | C13: Mất bộ test quyền/CSRF | D13: BE-16 | E13: Test chạy với CSRF bật thật | F13: Mở
A14: ISSUE-010 | B14: — | C14: Cấu hình production lỏng, test không chặn host lạ | D14: SF38 (#33) | E14: Settings bắt buộc env khi DEBUG=False; guard host test | F14: Đóng | G14: PR #33 merge vào dev1 (6f0bdc7)
A15: ISSUE-011 | B15: P1 | C15: API ngày ăn SF46: GET ghi dữ liệu, lỗi DB lộ ra, class_id sai bị bỏ qua | D15: BE-12 | E15: GET không ghi; validate từng dòng; lỗi không lộ | F15: Mở
