Workbook

Sheet Team
A2: SchoolFood phân công và tiến độ
A3: Điền tên tại cột B. Mỗi người bắt đầu bằng SF01–SF06. Tiến độ tính theo task, không phải giờ làm.
A4: Hoàn tất cần: trạng thái Hoàn tất + review Đạt + bằng chứng. Reviewer kiểm tra cả dependency trước khi duyệt.
A5: Mở M6 | B5: Chưa mở | C5: Chỉ TV1 mở sau M5 và xác nhận tài khoản, chi phí, domain.
A7: Mã | B7: Tên thành viên | C7: Vai trò | D7: Task local | E7: Đã xong | F7: Tỷ lệ local | G7: Đang làm | H7: Bị chặn
A8: TV1 | C8: Leader và tích hợp | D8: =COUNTIFS('Cong viec'!$C$6:$C$47,A8,'Cong viec'!$B$6:$B$47,"<>M6") -> 6 | E8: =SUMIFS('Cong viec'!$M$6:$M$47,'Cong viec'!$C$6:$C$47,A8,'Cong viec'!$B$6:$B$47,"<>M6") -> 0 | F8: =IF(D8=0,0,E8/D8) -> 0 | G8: =COUNTIFS('Cong viec'!$C$6:$C$47,A8,'Cong viec'!$I$6:$I$47,"Đang làm") -> 0 | H8: =COUNTIFS('Cong viec'!$C$6:$C$47,A8,'Cong viec'!$I$6:$I$47,"Bị chặn") -> 0
A9: TV2 | C9: Dữ liệu và nghiệp vụ backend | D9: =COUNTIFS('Cong viec'!$C$6:$C$47,A9,'Cong viec'!$B$6:$B$47,"<>M6") -> 6 | E9: =SUMIFS('Cong viec'!$M$6:$M$47,'Cong viec'!$C$6:$C$47,A9,'Cong viec'!$B$6:$B$47,"<>M6") -> 0 | F9: =IF(D9=0,0,E9/D9) -> 0 | G9: =COUNTIFS('Cong viec'!$C$6:$C$47,A9,'Cong viec'!$I$6:$I$47,"Đang làm") -> 0 | H9: =COUNTIFS('Cong viec'!$C$6:$C$47,A9,'Cong viec'!$I$6:$I$47,"Bị chặn") -> 0
A10: TV3 | C10: Giao diện chính | D10: =COUNTIFS('Cong viec'!$C$6:$C$47,A10,'Cong viec'!$B$6:$B$47,"<>M6") -> 6 | E10: =SUMIFS('Cong viec'!$M$6:$M$47,'Cong viec'!$C$6:$C$47,A10,'Cong viec'!$B$6:$B$47,"<>M6") -> 0 | F10: =IF(D10=0,0,E10/D10) -> 0 | G10: =COUNTIFS('Cong viec'!$C$6:$C$47,A10,'Cong viec'!$I$6:$I$47,"Đang làm") -> 0 | H10: =COUNTIFS('Cong viec'!$C$6:$C$47,A10,'Cong viec'!$I$6:$I$47,"Bị chặn") -> 0
A11: TV4 | C11: API và test backend | D11: =COUNTIFS('Cong viec'!$C$6:$C$47,A11,'Cong viec'!$B$6:$B$47,"<>M6") -> 6 | E11: =SUMIFS('Cong viec'!$M$6:$M$47,'Cong viec'!$C$6:$C$47,A11,'Cong viec'!$B$6:$B$47,"<>M6") -> 0 | F11: =IF(D11=0,0,E11/D11) -> 0 | G11: =COUNTIFS('Cong viec'!$C$6:$C$47,A11,'Cong viec'!$I$6:$I$47,"Đang làm") -> 0 | H11: =COUNTIFS('Cong viec'!$C$6:$C$47,A11,'Cong viec'!$I$6:$I$47,"Bị chặn") -> 0
A12: TV5 | C12: Giao diện và kiểm thử | D12: =COUNTIFS('Cong viec'!$C$6:$C$47,A12,'Cong viec'!$B$6:$B$47,"<>M6") -> 6 | E12: =SUMIFS('Cong viec'!$M$6:$M$47,'Cong viec'!$C$6:$C$47,A12,'Cong viec'!$B$6:$B$47,"<>M6") -> 0 | F12: =IF(D12=0,0,E12/D12) -> 0 | G12: =COUNTIFS('Cong viec'!$C$6:$C$47,A12,'Cong viec'!$I$6:$I$47,"Đang làm") -> 0 | H12: =COUNTIFS('Cong viec'!$C$6:$C$47,A12,'Cong viec'!$I$6:$I$47,"Bị chặn") -> 0
A13: TV6 | C13: QA và hỗ trợ tích hợp | D13: =COUNTIFS('Cong viec'!$C$6:$C$47,A13,'Cong viec'!$B$6:$B$47,"<>M6") -> 6 | E13: =SUMIFS('Cong viec'!$M$6:$M$47,'Cong viec'!$C$6:$C$47,A13,'Cong viec'!$B$6:$B$47,"<>M6") -> 0 | F13: =IF(D13=0,0,E13/D13) -> 0 | G13: =COUNTIFS('Cong viec'!$C$6:$C$47,A13,'Cong viec'!$I$6:$I$47,"Đang làm") -> 0 | H13: =COUNTIFS('Cong viec'!$C$6:$C$47,A13,'Cong viec'!$I$6:$I$47,"Bị chặn") -> 0
C14: Tổng local | D14: =SUM(D8:D13) -> 36 | E14: =SUM(E8:E13) -> 0 | F14: =IF(D14=0,0,E14/D14) -> 0 | G14: =SUM(G8:G13) -> 0 | H14: =SUM(H8:H13) -> 0
A17: Mốc | B17: Tên mốc | C17: Task | D17: Đã xong | E17: Tỷ lệ | F17: Case đạt | G17: Số case | H17: Phạm vi
A18: M0 | B18: Hiểu khung | C18: =COUNTIFS('Cong viec'!$B$6:$B$47,A18) -> 6 | D18: =SUMIFS('Cong viec'!$M$6:$M$47,'Cong viec'!$B$6:$B$47,A18) -> 0 | E18: =IF(C18=0,0,D18/C18) -> 0 | F18: =SUMIFS('Nghiem thu'!$J$6:$J$27,'Nghiem thu'!$B$6:$B$27,A18) -> 0 | G18: =COUNTIFS('Nghiem thu'!$B$6:$B$27,A18) -> 1 | H18: Bản local
A19: M1 | B19: Category đọc | C19: =COUNTIFS('Cong viec'!$B$6:$B$47,A19) -> 6 | D19: =SUMIFS('Cong viec'!$M$6:$M$47,'Cong viec'!$B$6:$B$47,A19) -> 0 | E19: =IF(C19=0,0,D19/C19) -> 0 | F19: =SUMIFS('Nghiem thu'!$J$6:$J$27,'Nghiem thu'!$B$6:$B$27,A19) -> 0 | G19: =COUNTIFS('Nghiem thu'!$B$6:$B$27,A19) -> 1 | H19: Bản local
A20: M2 | B20: Danh mục và auth | C20: =COUNTIFS('Cong viec'!$B$6:$B$47,A20) -> 6 | D20: =SUMIFS('Cong viec'!$M$6:$M$47,'Cong viec'!$B$6:$B$47,A20) -> 0 | E20: =IF(C20=0,0,D20/C20) -> 0 | F20: =SUMIFS('Nghiem thu'!$J$6:$J$27,'Nghiem thu'!$B$6:$B$27,A20) -> 0 | G20: =COUNTIFS('Nghiem thu'!$B$6:$B$27,A20) -> 4 | H20: Bản local
A21: M3 | B21: Nhập kho | C21: =COUNTIFS('Cong viec'!$B$6:$B$47,A21) -> 6 | D21: =SUMIFS('Cong viec'!$M$6:$M$47,'Cong viec'!$B$6:$B$47,A21) -> 0 | E21: =IF(C21=0,0,D21/C21) -> 0 | F21: =SUMIFS('Nghiem thu'!$J$6:$J$27,'Nghiem thu'!$B$6:$B$27,A21) -> 0 | G21: =COUNTIFS('Nghiem thu'!$B$6:$B$27,A21) -> 4 | H21: Bản local
A22: M4 | B22: Xuất kho | C22: =COUNTIFS('Cong viec'!$B$6:$B$47,A22) -> 6 | D22: =SUMIFS('Cong viec'!$M$6:$M$47,'Cong viec'!$B$6:$B$47,A22) -> 0 | E22: =IF(C22=0,0,D22/C22) -> 0 | F22: =SUMIFS('Nghiem thu'!$J$6:$J$27,'Nghiem thu'!$B$6:$B$27,A22) -> 0 | G22: =COUNTIFS('Nghiem thu'!$B$6:$B$27,A22) -> 4 | H22: Bản local
A23: M5 | B23: Kiểm kê và báo cáo | C23: =COUNTIFS('Cong viec'!$B$6:$B$47,A23) -> 6 | D23: =SUMIFS('Cong viec'!$M$6:$M$47,'Cong viec'!$B$6:$B$47,A23) -> 0 | E23: =IF(C23=0,0,D23/C23) -> 0 | F23: =SUMIFS('Nghiem thu'!$J$6:$J$27,'Nghiem thu'!$B$6:$B$27,A23) -> 0 | G23: =COUNTIFS('Nghiem thu'!$B$6:$B$27,A23) -> 6 | H23: Bản local
A24: M6 | B24: Deploy làm sau | C24: =COUNTIFS('Cong viec'!$B$6:$B$47,A24) -> 6 | D24: =SUMIFS('Cong viec'!$M$6:$M$47,'Cong viec'!$B$6:$B$47,A24) -> 0 | E24: =IF(C24=0,0,D24/C24) -> 0 | F24: =SUMIFS('Nghiem thu'!$J$6:$J$27,'Nghiem thu'!$B$6:$B$27,A24) -> 0 | G24: =COUNTIFS('Nghiem thu'!$B$6:$B$27,A24) -> 2 | H24: Mở sau khi chốt chi phí
A27: Cách dùng: lọc Cong viec theo TV, đọc thẻ SF trong Word, cập nhật trạng thái và bằng chứng sau mỗi buổi.
A28: Nghiem thu: điền Kết quả thực tế và Bằng chứng; chỉ chọn Đạt khi đã chạy. Không đánh dấu thay người chưa thử.
A29: Nếu đổi owner, đổi reviewer tương ứng; ô reviewer đỏ nghĩa là trùng người làm. Hạn dự kiến để trống chờ team chốt.
A30: Nguồn: skeleton repository và bộ hướng dẫn SchoolFood ngày 19/09/2026. Bộ này thay checklist 5 người cũ.

Sheet Cong viec
A2: SchoolFood công việc cho 6 thành viên
A3: Lọc Người làm theo TV. Tra mã SF trong hướng dẫn task. Ô vàng để cập nhật; cột M và N tự tính.
A4: Ngày 19/09/2026: chưa xác nhận task nào hoàn tất. M6 làm sau; TV1 mở tại Team!B5.
A5: Mã | B5: Mốc | C5: Người làm | D5: Reviewer | E5: Công việc | F5: Cần xong trước | G5: Điều kiện đạt | H5: Hạn dự kiến | I5: Trạng thái | J5: Review | K5: Bằng chứng | L5: Trở ngại hoặc bước tiếp | M5: Được tính xong | N5: Có thể bắt đầu
A6: SF01 | B6: M0 | C6: TV1 | D6: TV6 | E6: Chốt cách làm và chạy khung trên máy leader | F6: Không | G6: Leader chạy được khung và xác nhận tên của đủ 6 người. | I6: Chưa làm | J6: Chưa | M6: =IF(AND(I6="Hoàn tất",J6="Đạt",K6<>"",C6<>D6),1,0) -> 0 | N6: =IF(M6=1,"Xong","Có thể bắt đầu") -> Có thể bắt đầu
A7: SF02 | B7: M0 | C7: TV2 | D7: TV4 | E7: Đọc Django và PostgreSQL | F7: Không | G7: Giải thích được URL, view, truy vấn và JSON; có bằng chứng chạy local. | I7: Chưa làm | J7: Chưa | M7: =IF(AND(I7="Hoàn tất",J7="Đạt",K7<>"",C7<>D7),1,0) -> 0 | N7: =IF(M7=1,"Xong","Có thể bắt đầu") -> Có thể bắt đầu
A8: SF03 | B8: M0 | C8: TV3 | D8: TV5 | E8: Đọc React và vòng gọi API | F8: Không | G8: Giải thích được state, useEffect, fetch và proxy; không nhầm React truy cập DB trực tiếp. | I8: Chưa làm | J8: Chưa | M8: =IF(AND(I8="Hoàn tất",J8="Đạt",K8<>"",C8<>D8),1,0) -> 0 | N8: =IF(M8=1,"Xong","Có thể bắt đầu") -> Có thể bắt đầu
A9: SF04 | B9: M0 | C9: TV4 | D9: TV2 | E9: Chạy test mẫu và đọc lỗi | F9: Không | G9: Có test pass và biết tìm expected/actual khi test fail. | I9: Chưa làm | J9: Chưa | M9: =IF(AND(I9="Hoàn tất",J9="Đạt",K9<>"",C9<>D9),1,0) -> 0 | N9: =IF(M9=1,"Xong","Có thể bắt đầu") -> Có thể bắt đầu
A10: SF05 | B10: M0 | C10: TV5 | D10: TV3 | E10: Thử trạng thái lỗi của giao diện | F10: Không | G10: Biết phân biệt lỗi UI, API và database; bằng chứng gồm thành công và thất bại. | I10: Chưa làm | J10: Chưa | M10: =IF(AND(I10="Hoàn tất",J10="Đạt",K10<>"",C10<>D10),1,0) -> 0 | N10: =IF(M10=1,"Xong","Có thể bắt đầu") -> Có thể bắt đầu
A11: SF06 | B11: M0 | C11: TV6 | D11: TV1 | E11: Xác minh onboarding trên máy thứ hai | F11: Không | G11: Một người khác có thể chạy theo hướng dẫn; không đánh dấu thay ai chưa chạy. | I11: Chưa làm | J11: Chưa | M11: =IF(AND(I11="Hoàn tất",J11="Đạt",K11<>"",C11<>D11),1,0) -> 0 | N11: =IF(M11=1,"Xong","Có thể bắt đầu") -> Có thể bắt đầu
A12: SF07 | B12: M1 | C12: TV1 | D12: TV6 | E12: Chốt Category và cách chia branch | F12: SF01, SF02, SF03, SF04, SF05, SF06 | G12: Cả backend và frontend dùng một contract; cả 6 người đã qua M0. | I12: Chưa mở | J12: Chưa | M12: =IF(AND(I12="Hoàn tất",J12="Đạt",K12<>"",C12<>D12),1,0) -> 0 | N12: =IF(M12=1,"Xong",IF(AND(SUMIFS($M$6:$M$47,$A$6:$A$47,"SF01")=1,SUMIFS($M$6:$M$47,$A$6:$A$47,"SF02")=1,SUMIFS($M$6:$M$47,$A$6:$A$47,"SF03")=1,SUMIFS($M$6:$M$47,$A$6:$A$47,"SF04")=1,SUMIFS($M$6:$M$47,$A$6:$A$47,"SF05")=1,SUMIFS($M$6:$M$47,$A$6:$A$47,"SF06")=1),"Có thể bắt đầu","Chờ task trước")) -> Chờ task trước
A13: SF08 | B13: M1 | C13: TV2 | D13: TV4 | E13: Model Category và API danh sách | F13: SF07 | G13: Database giữ dữ liệu qua reload; GET trả đúng 2 nhóm hoặc mảng rỗng. | I13: Chưa mở | J13: Chưa | M13: =IF(AND(I13="Hoàn tất",J13="Đạt",K13<>"",C13<>D13),1,0) -> 0 | N13: =IF(M13=1,"Xong",IF(AND(SUMIFS($M$6:$M$47,$A$6:$A$47,"SF07")=1),"Có thể bắt đầu","Chờ task trước")) -> Chờ task trước
A14: SF09 | B14: M1 | C14: TV3 | D14: TV5 | E14: Trang danh sách Category | F14: SF08 | G14: Trang hiển thị đúng dữ liệu PostgreSQL, kể cả rỗng và mất kết nối. | I14: Chưa mở | J14: Chưa | M14: =IF(AND(I14="Hoàn tất",J14="Đạt",K14<>"",C14<>D14),1,0) -> 0 | N14: =IF(M14=1,"Xong",IF(AND(SUMIFS($M$6:$M$47,$A$6:$A$47,"SF08")=1),"Có thể bắt đầu","Chờ task trước")) -> Chờ task trước
A15: SF10 | B15: M1 | C15: TV4 | D15: TV2 | E15: Test Category đọc và ràng buộc | F15: SF08 | G15: Test pass trên database test riêng; không sửa tay dữ liệu local để test pass. | I15: Chưa mở | J15: Chưa | M15: =IF(AND(I15="Hoàn tất",J15="Đạt",K15<>"",C15<>D15),1,0) -> 0 | N15: =IF(M15=1,"Xong",IF(AND(SUMIFS($M$6:$M$47,$A$6:$A$47,"SF08")=1),"Có thể bắt đầu","Chờ task trước")) -> Chờ task trước
A16: SF11 | B16: M1 | C16: TV5 | D16: TV3 | E16: Review giao diện Category | F16: SF09 | G16: Không mất chữ quan trọng, lỗi dễ hiểu, không phát sinh dependency mới. | I16: Chưa mở | J16: Chưa | M16: =IF(AND(I16="Hoàn tất",J16="Đạt",K16<>"",C16<>D16),1,0) -> 0 | N16: =IF(M16=1,"Xong",IF(AND(SUMIFS($M$6:$M$47,$A$6:$A$47,"SF09")=1),"Có thể bắt đầu","Chờ task trước")) -> Chờ task trước
A17: SF12 | B17: M1 | C17: TV6 | D17: TV1 | E17: Nghiệm thu lát cắt Category | F17: SF09, SF10, SF11 | G17: Lát cắt DB → API → React chạy trên máy thứ hai. | I17: Chưa mở | J17: Chưa | M17: =IF(AND(I17="Hoàn tất",J17="Đạt",K17<>"",C17<>D17),1,0) -> 0 | N17: =IF(M17=1,"Xong",IF(AND(SUMIFS($M$6:$M$47,$A$6:$A$47,"SF09")=1,SUMIFS($M$6:$M$47,$A$6:$A$47,"SF10")=1,SUMIFS($M$6:$M$47,$A$6:$A$47,"SF11")=1),"Có thể bắt đầu","Chờ task trước")) -> Chờ task trước
A18: SF13 | B18: M2 | C18: TV1 | D18: TV6 | E18: Session đăng nhập và quyền API | F18: SF12 | G18: Manager đọc/ghi, viewer chỉ đọc; POST thiếu CSRF bị từ chối. | I18: Chưa mở | J18: Chưa | M18: =IF(AND(I18="Hoàn tất",J18="Đạt",K18<>"",C18<>D18),1,0) -> 0 | N18: =IF(M18=1,"Xong",IF(AND(SUMIFS($M$6:$M$47,$A$6:$A$47,"SF12")=1),"Có thể bắt đầu","Chờ task trước")) -> Chờ task trước
A19: SF14 | B19: M2 | C19: TV2 | D19: TV4 | E19: Danh mục đầy đủ và API ghi | F19: SF13 | G19: CRUD tối thiểu gồm xem/tạo/sửa/ngừng dùng; API không nhận chỉnh tồn trực tiếp. | I19: Chưa mở | J19: Chưa | M19: =IF(AND(I19="Hoàn tất",J19="Đạt",K19<>"",C19<>D19),1,0) -> 0 | N19: =IF(M19=1,"Xong",IF(AND(SUMIFS($M$6:$M$47,$A$6:$A$47,"SF13")=1),"Có thể bắt đầu","Chờ task trước")) -> Chờ task trước
A20: SF15 | B20: M2 | C20: TV3 | D20: TV5 | E20: Giao diện đăng nhập và danh mục thực phẩm | F20: SF13, SF14 | G20: Đăng nhập thật; xem/tạo/sửa thực phẩm được; hết session quay về login. | I20: Chưa mở | J20: Chưa | M20: =IF(AND(I20="Hoàn tất",J20="Đạt",K20<>"",C20<>D20),1,0) -> 0 | N20: =IF(M20=1,"Xong",IF(AND(SUMIFS($M$6:$M$47,$A$6:$A$47,"SF13")=1,SUMIFS($M$6:$M$47,$A$6:$A$47,"SF14")=1),"Có thể bắt đầu","Chờ task trước")) -> Chờ task trước
A21: SF16 | B21: M2 | C21: TV4 | D21: TV2 | E21: Test quyền và validation danh mục | F21: SF13, SF14 | G21: Test xác nhận cả response và trạng thái database khi lỗi. | I21: Chưa mở | J21: Chưa | M21: =IF(AND(I21="Hoàn tất",J21="Đạt",K21<>"",C21<>D21),1,0) -> 0 | N21: =IF(M21=1,"Xong",IF(AND(SUMIFS($M$6:$M$47,$A$6:$A$47,"SF13")=1,SUMIFS($M$6:$M$47,$A$6:$A$47,"SF14")=1),"Có thể bắt đầu","Chờ task trước")) -> Chờ task trước
A22: SF17 | B22: M2 | C22: TV5 | D22: TV3 | E22: Giao diện Supplier và lỗi dùng chung | F22: SF14, SF15 | G22: Supplier tạo/sửa/ngừng dùng được; lỗi hiển thị rõ và nút không gửi lặp. | I22: Chưa mở | J22: Chưa | M22: =IF(AND(I22="Hoàn tất",J22="Đạt",K22<>"",C22<>D22),1,0) -> 0 | N22: =IF(M22=1,"Xong",IF(AND(SUMIFS($M$6:$M$47,$A$6:$A$47,"SF14")=1,SUMIFS($M$6:$M$47,$A$6:$A$47,"SF15")=1),"Có thể bắt đầu","Chờ task trước")) -> Chờ task trước
A23: SF18 | B23: M2 | C23: TV6 | D23: TV1 | E23: Seed danh mục và nghiệm thu M2 | F23: SF15, SF16, SF17 | G23: Demo local lặp được; đủ tài khoản quyền; không nhân đôi danh mục. | I23: Chưa mở | J23: Chưa | M23: =IF(AND(I23="Hoàn tất",J23="Đạt",K23<>"",C23<>D23),1,0) -> 0 | N23: =IF(M23=1,"Xong",IF(AND(SUMIFS($M$6:$M$47,$A$6:$A$47,"SF15")=1,SUMIFS($M$6:$M$47,$A$6:$A$47,"SF16")=1,SUMIFS($M$6:$M$47,$A$6:$A$47,"SF17")=1),"Có thể bắt đầu","Chờ task trước")) -> Chờ task trước
A24: SF19 | B24: M3 | C24: TV1 | D24: TV6 | E24: Chốt model phiếu nhập và sổ kho | F24: SF18 | G24: Mô hình hỗ trợ nhiều dòng và không cho lặp cùng food trong một phiếu. | I24: Chưa mở | J24: Chưa | M24: =IF(AND(I24="Hoàn tất",J24="Đạt",K24<>"",C24<>D24),1,0) -> 0 | N24: =IF(M24=1,"Xong",IF(AND(SUMIFS($M$6:$M$47,$A$6:$A$47,"SF18")=1),"Có thể bắt đầu","Chờ task trước")) -> Chờ task trước
A25: SF20 | B25: M3 | C25: TV2 | D25: TV4 | E25: Nghiệp vụ chốt nhập và giá bình quân | F25: SF19 | G25: Chốt một lần duy nhất; lỗi bất kỳ dòng nào rollback cả phiếu. | I25: Chưa mở | J25: Chưa | M25: =IF(AND(I25="Hoàn tất",J25="Đạt",K25<>"",C25<>D25),1,0) -> 0 | N25: =IF(M25=1,"Xong",IF(AND(SUMIFS($M$6:$M$47,$A$6:$A$47,"SF19")=1),"Có thể bắt đầu","Chờ task trước")) -> Chờ task trước
A26: SF21 | B26: M3 | C26: TV3 | D26: TV5 | E26: Giao diện phiếu nhập | F26: SF22 | G26: Người dùng phân biệt Lưu nháp và Chốt; total do server trả. | I26: Chưa mở | J26: Chưa | M26: =IF(AND(I26="Hoàn tất",J26="Đạt",K26<>"",C26<>D26),1,0) -> 0 | N26: =IF(M26=1,"Xong",IF(AND(SUMIFS($M$6:$M$47,$A$6:$A$47,"SF22")=1),"Có thể bắt đầu","Chờ task trước")) -> Chờ task trước
A27: SF22 | B27: M3 | C27: TV4 | D27: TV2 | E27: API tạo nháp xem và chốt nhập | F27: SF19, SF20 | G27: API phân biệt draft/posted và error rõ; không có sửa/xóa posted. | I27: Chưa mở | J27: Chưa | M27: =IF(AND(I27="Hoàn tất",J27="Đạt",K27<>"",C27<>D27),1,0) -> 0 | N27: =IF(M27=1,"Xong",IF(AND(SUMIFS($M$6:$M$47,$A$6:$A$47,"SF19")=1,SUMIFS($M$6:$M$47,$A$6:$A$47,"SF20")=1),"Có thể bắt đầu","Chờ task trước")) -> Chờ task trước
A28: SF23 | B28: M3 | C28: TV5 | D28: TV3 | E28: Kiểm thử nhập kho và rollback | F28: SF20, SF22 | G28: AC08–AC10 có test tự động; không chỉ kiểm tra status 200. | I28: Chưa mở | J28: Chưa | M28: =IF(AND(I28="Hoàn tất",J28="Đạt",K28<>"",C28<>D28),1,0) -> 0 | N28: =IF(M28=1,"Xong",IF(AND(SUMIFS($M$6:$M$47,$A$6:$A$47,"SF20")=1,SUMIFS($M$6:$M$47,$A$6:$A$47,"SF22")=1),"Có thể bắt đầu","Chờ task trước")) -> Chờ task trước
A29: SF24 | B29: M3 | C29: TV6 | D29: TV1 | E29: Nghiệm thu nhập kho với dữ liệu chuẩn | F29: SF21, SF23 | G29: M3 chạy từ UI đến DB trên máy thứ hai; số liệu khớp bộ mẫu. | I29: Chưa mở | J29: Chưa | M29: =IF(AND(I29="Hoàn tất",J29="Đạt",K29<>"",C29<>D29),1,0) -> 0 | N29: =IF(M29=1,"Xong",IF(AND(SUMIFS($M$6:$M$47,$A$6:$A$47,"SF21")=1,SUMIFS($M$6:$M$47,$A$6:$A$47,"SF23")=1),"Có thể bắt đầu","Chờ task trước")) -> Chờ task trước
A30: SF25 | B30: M4 | C30: TV1 | D30: TV6 | E30: Chốt model và contract phiếu xuất | F30: SF24 | G30: Xuất có chứng từ và tham chiếu ledger; dùng cùng quy tắc bất biến như nhập. | I30: Chưa mở | J30: Chưa | M30: =IF(AND(I30="Hoàn tất",J30="Đạt",K30<>"",C30<>D30),1,0) -> 0 | N30: =IF(M30=1,"Xong",IF(AND(SUMIFS($M$6:$M$47,$A$6:$A$47,"SF24")=1),"Có thể bắt đầu","Chờ task trước")) -> Chờ task trước
A31: SF26 | B31: M4 | C31: TV2 | D31: TV4 | E31: Nghiệp vụ chốt xuất chống âm kho | F31: SF25 | G31: Không âm kho; giá xuất dùng giá tại lúc chốt; không ghi dở phiếu. | I31: Chưa mở | J31: Chưa | M31: =IF(AND(I31="Hoàn tất",J31="Đạt",K31<>"",C31<>D31),1,0) -> 0 | N31: =IF(M31=1,"Xong",IF(AND(SUMIFS($M$6:$M$47,$A$6:$A$47,"SF25")=1),"Có thể bắt đầu","Chờ task trước")) -> Chờ task trước
A32: SF27 | B32: M4 | C32: TV3 | D32: TV5 | E32: Giao diện xuất kho | F32: SF28 | G32: UI đi hết luồng draft → posted và phản ánh tồn mới. | I32: Chưa mở | J32: Chưa | M32: =IF(AND(I32="Hoàn tất",J32="Đạt",K32<>"",C32<>D32),1,0) -> 0 | N32: =IF(M32=1,"Xong",IF(AND(SUMIFS($M$6:$M$47,$A$6:$A$47,"SF28")=1),"Có thể bắt đầu","Chờ task trước")) -> Chờ task trước
A33: SF28 | B33: M4 | C33: TV4 | D33: TV2 | E33: API phiếu xuất | F33: SF25, SF26 | G33: API đúng contract và không thay tồn khi lỗi. | I33: Chưa mở | J33: Chưa | M33: =IF(AND(I33="Hoàn tất",J33="Đạt",K33<>"",C33<>D33),1,0) -> 0 | N33: =IF(M33=1,"Xong",IF(AND(SUMIFS($M$6:$M$47,$A$6:$A$47,"SF25")=1,SUMIFS($M$6:$M$47,$A$6:$A$47,"SF26")=1),"Có thể bắt đầu","Chờ task trước")) -> Chờ task trước
A34: SF29 | B34: M4 | C34: TV5 | D34: TV3 | E34: Test xuất đồng thời và trường hợp biên | F34: SF26, SF28 | G34: Không có âm kho khi hai người chốt đồng thời. | I34: Chưa mở | J34: Chưa | M34: =IF(AND(I34="Hoàn tất",J34="Đạt",K34<>"",C34<>D34),1,0) -> 0 | N34: =IF(M34=1,"Xong",IF(AND(SUMIFS($M$6:$M$47,$A$6:$A$47,"SF26")=1,SUMIFS($M$6:$M$47,$A$6:$A$47,"SF28")=1),"Có thể bắt đầu","Chờ task trước")) -> Chờ task trước
A35: SF30 | B35: M4 | C35: TV6 | D35: TV1 | E35: Nghiệm thu luồng nhập rồi xuất | F35: SF27, SF29 | G35: Nhập và xuất dùng cùng số liệu và đều chạy từ UI. | I35: Chưa mở | J35: Chưa | M35: =IF(AND(I35="Hoàn tất",J35="Đạt",K35<>"",C35<>D35),1,0) -> 0 | N35: =IF(M35=1,"Xong",IF(AND(SUMIFS($M$6:$M$47,$A$6:$A$47,"SF27")=1,SUMIFS($M$6:$M$47,$A$6:$A$47,"SF29")=1),"Có thể bắt đầu","Chờ task trước")) -> Chờ task trước
A36: SF31 | B36: M5 | C36: TV1 | D36: TV6 | E36: Chốt kiểm kê và tiêu chí hoàn tất local | F36: SF30 | G36: Dữ liệu đủ phát hiện kiểm kê cũ; cả team hiểu chênh lệch không đồng nghĩa gian lận. | I36: Chưa mở | J36: Chưa | M36: =IF(AND(I36="Hoàn tất",J36="Đạt",K36<>"",C36<>D36),1,0) -> 0 | N36: =IF(M36=1,"Xong",IF(AND(SUMIFS($M$6:$M$47,$A$6:$A$47,"SF30")=1),"Có thể bắt đầu","Chờ task trước")) -> Chờ task trước
A37: SF32 | B37: M5 | C37: TV2 | D37: TV4 | E37: Service và API kiểm kê | F37: SF31 | G37: Tồn 80 đếm 77 cho -3, tồn cuối 77; snapshot cũ bị từ chối. | I37: Chưa mở | J37: Chưa | M37: =IF(AND(I37="Hoàn tất",J37="Đạt",K37<>"",C37<>D37),1,0) -> 0 | N37: =IF(M37=1,"Xong",IF(AND(SUMIFS($M$6:$M$47,$A$6:$A$47,"SF31")=1),"Có thể bắt đầu","Chờ task trước")) -> Chờ task trước
A38: SF33 | B38: M5 | C38: TV3 | D38: TV5 | E38: Trang báo cáo tồn và lịch sử | F38: SF34 | G38: Báo cáo khớp kho, lọc đúng ngày và truy vết chứng từ. | I38: Chưa mở | J38: Chưa | M38: =IF(AND(I38="Hoàn tất",J38="Đạt",K38<>"",C38<>D38),1,0) -> 0 | N38: =IF(M38=1,"Xong",IF(AND(SUMIFS($M$6:$M$47,$A$6:$A$47,"SF34")=1),"Có thể bắt đầu","Chờ task trước")) -> Chờ task trước
A39: SF34 | B39: M5 | C39: TV4 | D39: TV2 | E39: API báo cáo tồn và sổ giao dịch | F39: SF31 | G39: Báo cáo chỉ đọc, số lượng khớp tổng quantity_delta; tiền theo rule làm tròn. | I39: Chưa mở | J39: Chưa | M39: =IF(AND(I39="Hoàn tất",J39="Đạt",K39<>"",C39<>D39),1,0) -> 0 | N39: =IF(M39=1,"Xong",IF(AND(SUMIFS($M$6:$M$47,$A$6:$A$47,"SF31")=1),"Có thể bắt đầu","Chờ task trước")) -> Chờ task trước
A40: SF35 | B40: M5 | C40: TV5 | D40: TV3 | E40: Giao diện kiểm kê | F40: SF32 | G40: Phân biệt chưa nhập với 0; kiểm kê cũ không thể ghi đè tồn. | I40: Chưa mở | J40: Chưa | M40: =IF(AND(I40="Hoàn tất",J40="Đạt",K40<>"",C40<>D40),1,0) -> 0 | N40: =IF(M40=1,"Xong",IF(AND(SUMIFS($M$6:$M$47,$A$6:$A$47,"SF32")=1),"Có thể bắt đầu","Chờ task trước")) -> Chờ task trước
A41: SF36 | B41: M5 | C41: TV6 | D41: TV1 | E41: Nghiệm thu toàn bộ MVP local | F41: SF32, SF33, SF34, SF35 | G41: MVP local đủ bằng chứng; không đánh dấu xong chỉ dựa vào build pass. | I41: Chưa mở | J41: Chưa | M41: =IF(AND(I41="Hoàn tất",J41="Đạt",K41<>"",C41<>D41),1,0) -> 0 | N41: =IF(M41=1,"Xong",IF(AND(SUMIFS($M$6:$M$47,$A$6:$A$47,"SF32")=1,SUMIFS($M$6:$M$47,$A$6:$A$47,"SF33")=1,SUMIFS($M$6:$M$47,$A$6:$A$47,"SF34")=1,SUMIFS($M$6:$M$47,$A$6:$A$47,"SF35")=1),"Có thể bắt đầu","Chờ task trước")) -> Chờ task trước
...

Sheet Nghiem thu
A2: SchoolFood checklist nghiệm thu
A3: Ghi actual và bằng chứng sau khi chạy. Chưa chạy không có nghĩa là Đạt. AC21–AC22 dành cho M6 làm sau.
A5: Mã | B5: Mốc | C5: Người kiểm tra | D5: Task liên quan | E5: Thiết lập và thao tác | F5: Kết quả mong đợi | G5: Kết quả thực tế | H5: Trạng thái | I5: Bằng chứng | J5: Được tính đạt
A6: AC01 | B6: M0 | C6: TV6 | D6: SF01–SF06 | E6: Mỗi người tự chạy Compose, migrate, hello, test và build. | F6: Đủ 6 bằng chứng và 6 lời giải thích vòng request. | H6: Chưa chạy | J6: =IF(AND(H6="Đạt",G6<>"",I6<>""),1,0) -> 0
A7: AC02 | B7: M1 | C7: TV6 | D7: SF08–SF12 | E7: Tạo 2 Category rồi xem API và UI, reload trang. | F7: Hai nhóm giống nhau ở DB/API/UI; empty/error state rõ. | H7: Chưa chạy | J7: =IF(AND(H7="Đạt",G7<>"",I7<>""),1,0) -> 0
A8: AC03 | B8: M2 | C8: TV4 | D8: SF14,SF16 | E8: Gửi code trùng, name rỗng, category không tồn tại, field quantity tự đặt. | F8: 400/409 phù hợp; không tạo hoặc sửa dữ liệu sai. | H8: Chưa chạy | J8: =IF(AND(H8="Đạt",G8<>"",I8<>""),1,0) -> 0
A9: AC04 | B9: M2 | C9: TV4 | D9: SF13,SF16 | E9: Thử chưa login, sai password, viewer ghi, POST thiếu CSRF và logout. | F9: 401/403 theo contract; request hợp lệ thành công; logout mất quyền. | H9: Chưa chạy | J9: =IF(AND(H9="Đạt",G9<>"",I9<>""),1,0) -> 0
A10: AC05 | B10: M2 | C10: TV5 | D10: SF14–SF17 | E10: Tạo/sửa/ngừng dùng Food và Supplier bằng manager. | F10: Reload giữ dữ liệu; viewer chỉ xem; tồn không chỉnh qua form. | H10: Chưa chạy | J10: =IF(AND(H10="Đạt",G10<>"",I10<>""),1,0) -> 0
A11: AC06 | B11: M2 | C11: TV6 | D11: SF18 | E11: Chạy seed danh mục 2 lần trên local. | F11: Không trùng code; quantity/avg vẫn bằng 0. | H11: Chưa chạy | J11: =IF(AND(H11="Đạt",G11<>"",I11<>""),1,0) -> 0
A12: AC07 | B12: M3 | C12: TV4 | D12: SF19–SF22 | E12: Tạo Receipt draft có 2 dòng rồi xem tồn. | F12: Draft có id; quantity và ledger chưa đổi. | H12: Chưa chạy | J12: =IF(AND(H12="Đạt",G12<>"",I12<>""),1,0) -> 0
A13: AC08 | B13: M3 | C13: TV5 | D13: SF20,SF23 | E13: Chốt nhập Gạo 50 × 90000 rồi 50 × 110000. | F13: Tồn 100.000 kg; avg 100000.00; hai ledger IN. | H13: Chưa chạy | J13: =IF(AND(H13="Đạt",G13<>"",I13<>""),1,0) -> 0
A14: AC09 | B14: M3 | C14: TV5 | D14: SF20,SF23 | E14: Phiếu 2 dòng, 1 dòng quantity âm hoặc food không active. | F14: Toàn phiếu bị từ chối; tồn, status, ledger đều không đổi. | H14: Chưa chạy | J14: =IF(AND(H14="Đạt",G14<>"",I14<>""),1,0) -> 0
A15: AC10 | B15: M3 | C15: TV5 | D15: SF22,SF23 | E15: Chốt cùng receipt_id lần thứ hai. | F15: 409; không tăng tồn hoặc ledger lần hai. | H15: Chưa chạy | J15: =IF(AND(H15="Đạt",G15<>"",I15<>""),1,0) -> 0
A16: AC11 | B16: M4 | C16: TV6 | D16: SF26–SF30 | E16: Sau AC08, chốt xuất 20 kg. | F16: Tồn 80.000; avg 100000.00; giá trị xuất 2000000.00. | H16: Chưa chạy | J16: =IF(AND(H16="Đạt",G16<>"",I16<>""),1,0) -> 0
A17: AC12 | B17: M4 | C17: TV5 | D17: SF26,SF29 | E17: Khi tồn 80, thử xuất 81; thêm case phiếu 2 dòng thiếu 1 dòng. | F17: 409; rollback mọi dòng, không âm kho. | H17: Chưa chạy | J17: =IF(AND(H17="Đạt",G17<>"",I17<>""),1,0) -> 0
... A27: AC22 | B27: M6 | C27: TV6 | D27: SF38,SF42 | E27: Backup/restore vào DB thử và diễn tập rollback app staging. | F27: Dữ liệu phục hồi đúng; có hướng dẫn migration; không reset production. | H27: Chưa chạy | J27: =IF(AND(H27="Đạt",G27<>"",I27<>""),1,0) -> 0
